Workbook
Name Slicer_Country: #N/A
Name Slicer_GDP_Category: #N/A
Name Slicer_Performace_category: #N/A
Name Slicer_Region: #N/A

Sheet Olympics Data
A1: Country | B1: Country_code | C1: Region | D1: Gold | E1: Silver | F1: Bronze | G1: Total | H1: GDP | I1: GDP_year | J1: Population
A2: United States | B2: USA | C2: North America | D2: 40 | E2: 44 | F2: 42 | G2: 126 | H2: 81695.19 | I2: 2023 | J2: 334.9
A3: China | B3: CHN | C3: Asia | D3: 40 | E3: 27 | F3: 24 | G3: 91 | H3: 12614.06 | I3: 2023 | J3: 1410.7
A4: Japan | B4: JPN | C4: Asia | D4: 20 | E4: 12 | F4: 13 | G4: 45 | H4: 33834.39 | I4: 2023 | J4: 124.5
A5: Australia | B5: AUS | C5: Oceania | D5: 18 | E5: 19 | F5: 16 | G5: 53 | H5: 64711.77 | I5: 2023 | J5: 26.6
A6: France | B6: FRA | C6: Europe | D6: 16 | E6: 26 | F6: 22 | G6: 64 | H6: 44460.82 | I6: 2023 | J6: 68.2
A7: Netherlands | B7: NLD | C7: Europe | D7: 15 | E7: 7 | F7: 12 | G7: 34 | H7: 62536.73 | I7: 2023 | J7: 17.9
A8: Great Britain | B8: GBR | C8: Europe | D8: 14 | E8: 22 | F8: 29 | G8: 65 | H8: 48866.6 | I8: 2023 | J8: 68.3
A9: South Korea | B9: KOR | C9: Asia | D9: 13 | E9: 9 | F9: 10 | G9: 32 | H9: 33121.37 | I9: 2023 | J9: 51.7
A10: Italy | B10: ITA | C10: Europe | D10: 12 | E10: 13 | F10: 15 | G10: 40 | H10: 38373.17 | I10: 2023 | J10: 58.8
A11: Germany | B11: DEU | C11: Europe | D11: 12 | E11: 13 | F11: 8 | G11: 33 | H11: 52745.76 | I11: 2023 | J11: 84.5
A12: New Zealand | B12: NZL | C12: Oceania | D12: 10 | E12: 7 | F12: 3 | G12: 20 | H12: 48527.83 | I12: 2023 | J12: 5.2
A13: Canada | B13: CAN | C13: North America | D13: 9 | E13: 7 | F13: 11 | G13: 27 | H13: 53371.7 | I13: 2023 | J13: 40.1
... A91: Zambia | B91: ZMB | C91: Africa | D91: 0 | E91: 0 | F91: 1 | G91: 1 | H91: 1369.13 | I91: 2023 | J91: 20.6

Sheet new columns
A1: Country | B1: Country_code | C1: Region | D1: Gold | E1: Silver | F1: Bronze | G1: Total | H1: Performance | I1: GDP | J1: GDP_year | K1: Population | L1: Gold % | M1: Silver% | N1: Bronze% | O1: Medals efficiency | P1: Weighted medal score | Q1: GDP per medal | R1: GDP Contribution | S1: GDP Category | T1: Performace category
A2: United States | B2: USA | C2: North America | D2: 40 | E2: 44 | F2: 42 | G2: 126 | H2: =IF(G2>=100,"Excellent","Needs improvement") -> Excellent | I2: 81695.19 | J2: 2023 | K2: 334.9 | L2: =D2/G2 -> 0.31746032 | M2: =E2/G2 -> 0.34920635 | N2: =F2/G2 -> 0.33333333 | O2: =Table1456[[#This Row],[Total]]/Table1456[[#This Row],[Population]] -> 0.37623171 | P2: =(Table1456[[#This Row],[Gold]]*3)+(Table1456[[#This Row],[Silver]]*2)+(Table1456[[#This Row],[Bronze]]*1) -> 250 | Q2: =I2/G2 -> 648.37452 | R2: =PRODUCT(Table1456[[#This Row],[GDP]]*Table1456[[#This Row],[Gold]]) -> 3267807.6 | S2: =IF(I2>=50000,"High GDP","Low GDP") -> High GDP | T2: =IF(D2>=20,"Top performer","Low performer") -> Top performer
A3: China | B3: CHN | C3: Asia | D3: 40 | E3: 27 | F3: 24 | G3: 91 | H3: =IF(G3>=100,"Excellent","Needs improvement") -> Needs improvement | I3: 12614.06 | J3: 2023 | K3: 1410.7 | L3: =D3/G3 -> 0.43956044 | M3: =E3/G3 -> 0.2967033 | N3: =F3/G3 -> 0.26373626 | O3: =Table1456[[#This Row],[Total]]/Table1456[[#This Row],[Population]] -> 0.064506982 | P3: =(Table1456[[#This Row],[Gold]]*3)+(Table1456[[#This Row],[Silver]]*2)+(Table1456[[#This Row],[Bronze]]*1) -> 198 | Q3: =I3/G3 -> 138.61604 | R3: =PRODUCT(Table1456[[#This Row],[GDP]]*Table1456[[#This Row],[Gold]]) -> 504562.4 | S3: =IF(I3>=50000,"High GDP","Low GDP") -> Low GDP | T3: =IF(D3>=20,"Top performer","Low performer") -> Top performer
A4: Japan | B4: JPN | C4: Asia | D4: 20 | E4: 12 | F4: 13 | G4: 45 | H4: =IF(G4>=100,"Excellent","Needs improvement") -> Needs improvement | I4: 33834.39 | J4: 2023 | K4: 124.5 | L4: =D4/G4 -> 0.44444444 | M4: =E4/G4 -> 0.26666667 | N4: =F4/G4 -> 0.28888889 | O4: =Table1456[[#This Row],[Total]]/Table1456[[#This Row],[Population]] -> 0.36144578 | P4: =(Table1456[[#This Row],[Gold]]*3)+(Table1456[[#This Row],[Silver]]*2)+(Table1456[[#This Row],[Bronze]]*1) -> 97 | Q4: =I4/G4 -> 751.87533 | R4: =PRODUCT(Table1456[[#This Row],[GDP]]*Table1456[[#This Row],[Gold]]) -> 676687.8 | S4: =IF(I4>=50000,"High GDP","Low GDP") -> Low GDP | T4: =IF(D4>=20,"Top performer","Low performer") -> Top performer
A5: Australia | B5: AUS | C5: Oceania | D5: 18 | E5: 19 | F5: 16 | G5: 53 | H5: =IF(G5>=100,"Excellent","Needs improvement") -> Needs improvement | I5: 64711.77 | J5: 2023 | K5: 26.6 | L5: =D5/G5 -> 0.33962264 | M5: =E5/G5 -> 0.35849057 | N5: =F5/G5 -> 0.30188679 | O5: =Table1456[[#This Row],[Total]]/Table1456[[#This Row],[Population]] -> 1.9924812 | P5: =(Table1456[[#This Row],[Gold]]*3)+(Table1456[[#This Row],[Silver]]*2)+(Table1456[[#This Row],[Bronze]]*1) -> 108 | Q5: =I5/G5 -> 1220.9768 | R5: =PRODUCT(Table1456[[#This Row],[GDP]]*Table1456[[#This Row],[Gold]]) -> 1164811.9 | S5: =IF(I5>=50000,"High GDP","Low GDP") -> High GDP | T5: =IF(D5>=20,"Top performer","Low performer") -> Low performer
A6: France | B6: FRA | C6: Europe | D6: 16 | E6: 26 | F6: 22 | G6: 64 | H6: =IF(G6>=100,"Excellent","Needs improvement") -> Needs improvement | I6: 44460.82 | J6: 2023 | K6: 68.2 | L6: =D6/G6 -> 0.25 | M6: =E6/G6 -> 0.40625 | N6: =F6/G6 -> 0.34375 | O6: =Table1456[[#This Row],[Total]]/Table1456[[#This Row],[Population]] -> 0.93841642 | P6: =(Table1456[[#This Row],[Gold]]*3)+(Table1456[[#This Row],[Silver]]*2)+(Table1456[[#This Row],[Bronze]]*1) -> 122 | Q6: =I6/G6 -> 694.70031 | R6: =PRODUCT(Table1456[[#This Row],[GDP]]*Table1456[[#This Row],[Gold]]) -> 711373.12 | S6: =IF(I6>=50000,"High GDP","Low GDP") -> Low GDP | T6: =IF(D6>=20,"Top performer","Low performer") -> Low performer
A7: Netherlands | B7: NLD | C7: Europe | D7: 15 | E7: 7 | F7: 12 | G7: 34 | H7: =IF(G7>=100,"Excellent","Needs improvement") -> Needs improvement | I7: 62536.73 | J7: 2023 | K7: 17.9 | L7: =D7/G7 -> 0.44117647 | M7: =E7/G7 -> 0.20588235 | N7: =F7/G7 -> 0.35294118 | O7: =Table1456[[#This Row],[Total]]/Table1456[[#This Row],[Population]] -> 1.8994413 | P7: =(Table1456[[#This Row],[Gold]]*3)+(Table1456[[#This Row],[Silver]]*2)+(Table1456[[#This Row],[Bronze]]*1) -> 71 | Q7: =I7/G7 -> 1839.3156 | R7: =PRODUCT(Table1456[[#This Row],[GDP]]*Table1456[[#This Row],[Gold]]) -> 938050.95 | S7: =IF(I7>=50000,"High GDP","Low GDP") -> High GDP | T7: =IF(D7>=20,"Top performer","Low performer") -> Low performer
A8: Great Britain | B8: GBR | C8: Europe | D8: 14 | E8: 22 | F8: 29 | G8: 65 | H8: =IF(G8>=100,"Excellent","Needs improvement") -> Needs improvement | I8: 48866.6 | J8: 2023 | K8: 68.3 | L8: =D8/G8 -> 0.21538462 | M8: =E8/G8 -> 0.33846154 | N8: =F8/G8 -> 0.44615385 | O8: =Table1456[[#This Row],[Total]]/Table1456[[#This Row],[Population]] -> 0.95168375 | P8: =(Table1456[[#This Row],[Gold]]*3)+(Table1456[[#This Row],[Silver]]*2)+(Table1456[[#This Row],[Bronze]]*1) -> 115 | Q8: =I8/G8 -> 751.79385 | R8: =PRODUCT(Table1456[[#This Row],[GDP]]*Table1456[[#This Row],[Gold]]) -> 684132.4 | S8: =IF(I8>=50000,"High GDP","Low GDP") -> Low GDP | T8: =IF(D8>=20,"Top performer","Low performer") -> Low performer
A9: South Korea | B9: KOR | C9: Asia | D9: 13 | E9: 9 | F9: 10 | G9: 32 | H9: =IF(G9>=100,"Excellent","Needs improvement") -> Needs improvement | I9: 33121.37 | J9: 2023 | K9: 51.7 | L9: =D9/G9 -> 0.40625 | M9: =E9/G9 -> 0.28125 | N9: =F9/G9 -> 0.3125 | O9: =Table1456[[#This Row],[Total]]/Table1456[[#This Row],[Population]] -> 0.61895551 | P9: =(Table1456[[#This Row],[Gold]]*3)+(Table1456[[#This Row],[Silver]]*2)+(Table1456[[#This Row],[Bronze]]*1) -> 67 | Q9: =I9/G9 -> 1035.0428 | R9: =PRODUCT(Table1456[[#This Row],[GDP]]*Table1456[[#This Row],[Gold]]) -> 430577.81 | S9: =IF(I9>=50000,"High GDP","Low GDP") -> Low GDP | T9: =IF(D9>=20,"Top performer","Low performer") -> Low performer
A10: Italy | B10: ITA | C10: Europe | D10: 12 | E10: 13 | F10: 15 | G10: 40 | H10: =IF(G10>=100,"Excellent","Needs improvement") -> Needs improvement | I10: 38373.17 | J10: 2023 | K10: 58.8 | L10: =D10/G10 -> 0.3 | M10: =E10/G10 -> 0.325 | N10: =F10/G10 -> 0.375 | O10: =Table1456[[#This Row],[Total]]/Table1456[[#This Row],[Population]] -> 0.68027211 | P10: =(Table1456[[#This Row],[Gold]]*3)+(Table1456[[#This Row],[Silver]]*2)+(Table1456[[#This Row],[Bronze]]*1) -> 77 | Q10: =I10/G10 -> 959.32925 | R10: =PRODUCT(Table1456[[#This Row],[GDP]]*Table1456[[#This Row],[Gold]]) -> 460478.04 | S10: =IF(I10>=50000,"High GDP","Low GDP") -> Low GDP | T10: =IF(D10>=20,"Top performer","Low performer") -> Low performer
A11: Germany | B11: DEU | C11: Europe | D11: 12 | E11: 13 | F11: 8 | G11: 33 | H11: =IF(G11>=100,"Excellent","Needs improvement") -> Needs improvement | I11: 52745.76 | J11: 2023 | K11: 84.5 | L11: =D11/G11 -> 0.36363636 | M11: =E11/G11 -> 0.39393939 | N11: =F11/G11 -> 0.24242424 | O11: =Table1456[[#This Row],[Total]]/Table1456[[#This Row],[Population]] -> 0.39053254 | P11: =(Table1456[[#This Row],[Gold]]*3)+(Table1456[[#This Row],[Silver]]*2)+(Table1456[[#This Row],[Bronze]]*1) -> 70 | Q11: =I11/G11 -> 1598.3564 | R11: =PRODUCT(Table1456[[#This Row],[GDP]]*Table1456[[#This Row],[Gold]]) -> 632949.12 | S11: =IF(I11>=50000,"High GDP","Low GDP") -> High GDP | T11: =IF(D11>=20,"Top performer","Low performer") -> Low performer
A12: New Zealand | B12: NZL | C12: Oceania | D12: 10 | E12: 7 | F12: 3 | G12: 20 | H12: =IF(G12>=100,"Excellent","Needs improvement") -> Needs improvement | I12: 48527.83 | J12: 2023 | K12: 5.2 | L12: =D12/G12 -> 0.5 | M12: =E12/G12 -> 0.35 | N12: =F12/G12 -> 0.15 | O12: =Table1456[[#This Row],[Total]]/Table1456[[#This Row],[Population]] -> 3.8461538 | P12: =(Table1456[[#This Row],[Gold]]*3)+(Table1456[[#This Row],[Silver]]*2)+(Table1456[[#This Row],[Bronze]]*1) -> 47 | Q12: =I12/G12 -> 2426.3915 | R12: =PRODUCT(Table1456[[#This Row],[GDP]]*Table1456[[#This Row],[Gold]]) -> 485278.3 | S12: =IF(I12>=50000,"High GDP","Low GDP") -> Low GDP | T12: =IF(D12>=20,"Top performer","Low performer") -> Low performer
A13: Canada | B13: CAN | C13: North America | D13: 9 | E13: 7 | F13: 11 | G13: 27 | H13: =IF(G13>=100,"Excellent","Needs improvement") -> Needs improvement | I13: 53371.7 | J13: 2023 | K13: 40.1 | L13: =D13/G13 -> 0.33333333 | M13: =E13/G13 -> 0.25925926 | N13: =F13/G13 -> 0.40740741 | O13: =Table1456[[#This Row],[Total]]/Table1456[[#This Row],[Population]] -> 0.67331671 | P13: =(Table1456[[#This Row],[Gold]]*3)+(Table1456[[#This Row],[Silver]]*2)+(Table1456[[#This Row],[Bronze]]*1) -> 52 | Q13: =I13/G13 -> 1976.7296 | R13: =PRODUCT(Table1456[[#This Row],[GDP]]*Table1456[[#This Row],[Gold]]) -> 480345.3 | S13: =IF(I13>=50000,"High GDP","Low GDP") -> High GDP | T13: =IF(D13>=20,"Top performer","Low performer") -> Low performer
... A91: Zambia | B91: ZMB | C91: Africa | D91: 0 | E91: 0 | F91: 1 | G91: 1 | H91: =IF(G91>=100,"Excellent","Needs improvement") -> Needs improvement | I91: 1369.13 | J91: 2023 | K91: 20.6 | L91: =D91/G91 -> 0 | M91: =E91/G91 -> 0 | N91: =F91/G91 -> 1 | O91: =Table1456[[#This Row],[Total]]/Table1456[[#This Row],[Population]] -> 0.048543689 | P91: =(Table1456[[#This Row],[Gold]]*3)+(Table1456[[#This Row],[Silver]]*2)+(Table1456[[#This Row],[Bronze]]*1) -> 1 | Q91: =I91/G91 -> 1369.13 | R91: =PRODUCT(Table1456[[#This Row],[GDP]]*Table1456[[#This Row],[Gold]]) -> 0 | S91: =IF(I91>=50000,"High GDP","Low GDP") -> Low GDP | T91: =IF(D91>=20,"Top performer","Low performer") -> Low performer

Sheet Formula working
A1: SUM Formula Questions | D1: VLOOKUP TABLE
A2: Calculate the total number of Gold medals won by all countries. | B2: =SUM(Filters!D:D) -> 328 | D2: Country | E2: Performance table
A3: Calculate the total number of Silver medals won. | B3: =SUM(Filters!E:E) -> 327 | D3: USA | E3: excellent
A4: Calculate the total number of Bronze medals won. | B4: =SUM(Filters!F:F) -> 383 | D4: India | E4: average
A5: Calculate the total medals won by all countries. | B5: =SUM(Filters!G:G) -> 1038 | D5: China | E5: excellent
A6: Calculate the total GDP of all countries. | B6: =SUM(Filters!I:I) -> 2203024.8 | D6: Japan | E6: good
A7: Calculate the total population represented in the dataset. | B7: =SUM(Filters!K:K) -> 6212.5 | D7: Brazil | E7: avearge
A9: AVERAGE Formula Questions | D9: question: find the performance category of india from the given table
A10: Find the average number of Gold medals won. | B10: =AVERAGE(Filters!D:D) -> 3.6444444 | D10: answer: | E10: =VLOOKUP("India",D2:E7,2,FALSE) -> average
A11: Find the average number of Silver medals won. | B11: =AVERAGE(Filters!E:E) -> 3.6333333
A12: Find the average number of Bronze medals won. | B12: =AVERAGE(Filters!F:F) -> 4.2555556
A13: Find the average total medals per country. | B13: =AVERAGE(Filters!G:G) -> 11.533333
A14: Find the average GDP of all countries. | B14: =AVERAGE(Filters!I:I) -> 24478.054
A15: Find the average population of the participating countries. | B15: =AVERAGE(Filters!K:K) -> 69.027778
A17: MIN & MAX Questions
A18: Which country has the highest GDP? | B18: =MAX(Filters!I:I) -> 103684.88
A19: Which country has the lowest GDP? | B19: =MIN(Filters!I:I) -> 1014.21
A20: What is the highest number of Gold medals won? | B20: =MAX(Filters!D:D) -> 40
A21: What is the lowest number of Gold medals won? | B21: =MIN(Filters!D:D) -> 0
A22: What is the maximum population in the dataset? | B22: =MAX(Filters!K:K) -> 1428.6
A23: What is the minimum population in the dataset? | B23: =MIN(Filters!K:K) -> 0.1
A25: Multiplication Questions
A26: Create new calculated columns.
A27: Calculate GDP Contribution
A28: Calculate Medal Efficiency
A29: Calculate Weighted Medal Score using:
A30: Gold × 3
A31: Silver × 2
A32: Bronze × 1
A34: IF Formula Question
A35: If Total Medals ≥ 100, display "Excellent", otherwise "Needs Improvement".
A36: If Gold Medals ≥ 20, display "Top Performer", otherwise "Average Performer".
A37: If GDP ≥ 50,000, display "High GDP", otherwise "Low GDP".
... A41: IF + AND Questions
A42: If Gold ≥ 20 AND GDP ≥ 50,000, display "Strong Economy & Strong Performance". | B42: =IF(AND(D2>=20,Filters!I2>=50000),"Strong economy and Strong permormance","Others") -> Strong economy and Strong permormance
A43: If Total Medals ≥ 50 AND Population ≥ 50 million, display "High Performing Nation".
A44: If Gold ≥ 10 AND Region = Asia, display "Top Asian Nation".
A46: COUNTIF Questions
A47: Count european countries with Gold medals greater than 10. | B47: =COUNTIFS(C:C,"Europe",Filters!D:D,">=10") -> 0
A48: Count the asian countries with Total medals greater than 50. | B48: =COUNTIFS(Filters!C:C,"Asia",Filters!G:G,">50") -> 1
...

Sheet Dashboard

Sheet Pivot table
A3: Row Labels | B3: Sum of Total
A4: Africa | B4: 39
A5: Asia | B5: 282
A6: Caribbean | B6: 7
A7: Europe | B7: 415
A8: North America | B8: 178
A9: Oceania | B9: 74
A10: South America | B10: 36
A11: Grand Total | B11: 1031
A13: Row Labels | B13: Average of Gold % | C13: Average of Silver% | D13: Average of Bronze%
A14: Africa | B14: 0.30113636 | C14: 0.25820707 | D14: 0.44065657
A15: Asia | B15: 0.24408137 | C15: 0.29366811 | D15: 0.46225052
A16: Caribbean | B16: 0.375 | C16: 0.125 | D16: 0.5
A17: Europe | B17: #DIV/0! | C17: #DIV/0! | D17: #DIV/0!
A18: North America | B18: 0.2675737 | C18: 0.25993953 | D18: 0.47248677
A19: Oceania | B19: 0.27987421 | C19: 0.56949686 | D19: 0.15062893
A20: South America | B20: 0.16904762 | C20: 0.47619048 | D20: 0.3547619
A21: Grand Total | B21: #DIV/0! | C21: #DIV/0! | D21: #DIV/0!
A22: Row Labels | B22: Average of GDP per medal
A23: Africa | B23: 1679.4332
A24: Asia | B24: 9078.7618
A25: Caribbean | B25: 9891.325
A26: Europe | B26: #DIV/0!
A27: North America | B27: 2757.7295
A28: Oceania | B28: 3171.8428
A29: South America | B29: 6161.2686
A30: Grand Total | B30: #DIV/0!
A31: Row Labels | B31: Count of Country
A32: High GDP | B32: 17
A33: Low GDP | B33: 73
A34: Grand Total | B34: 90
A36: Row Labels | B36: Count of Country
A37: Low performer | B37: 87
A38: Top performer | B38: 3
A39: Grand Total | B39: 90
A41: Row Labels | B41: Sum of Gold
A42: India | B42: 0
A43: Brazil | B43: 3
A44: Albania | B44: 0
A45: Algeria | B45: 2
...

Sheet sorting
A1: Country | B1: Country_code | C1: Region | D1: Gold | E1: Silver | F1: Bronze | G1: Total | H1: Performance | I1: GDP | J1: GDP_year | K1: Population | L1: Gold % | M1: Silver% | N1: Bronze% | O1: GDP per medal | P1: GDP Category | Q1: Performace category
A2: Ireland | B2: IRL | C2: Europe | D2: 4 | E2: 0 | F2: 3 | H2: =IF(G2>=100,"Excellent","Needs improvement") -> Needs improvement | I2: 103684.88 | J2: 2023 | K2: 5.3 | L2: =D2/G2 -> #DIV/0! | M2: =E2/G2 -> #DIV/0! | N2: =F2/G2 -> #DIV/0! | O2: =I2/G2 -> #DIV/0! | P2: =IF(I2>=50000,"High GDP","Low GDP") -> High GDP | Q2: =IF(D2>=20,"Top performer","Low performer") -> Low performer
A3: Pakistan | B3: PAK | C3: Asia | D3: 1 | E3: 0 | F3: 0 | G3: 1 | H3: =IF(G3>=100,"Excellent","Needs improvement") -> Needs improvement | I3: 1407.02 | J3: 2023 | K3: 240.5 | L3: =D3/G3 -> 1 | M3: =E3/G3 -> 0 | N3: =F3/G3 -> 0 | O3: =I3/G3 -> 1407.02 | P3: =IF(I3>=50000,"High GDP","Low GDP") -> Low GDP | Q3: =IF(D3>=20,"Top performer","Low performer") -> Low performer
A4: Dominica | B4: DMA | C4: Caribbean | D4: 1 | E4: 0 | F4: 0 | G4: 1 | H4: =IF(G4>=100,"Excellent","Needs improvement") -> Needs improvement | I4: 8953.9 | J4: 2023 | K4: 0.1 | L4: =D4/G4 -> 1 | M4: =E4/G4 -> 0 | N4: =F4/G4 -> 0 | O4: =I4/G4 -> 8953.9 | P4: =IF(I4>=50000,"High GDP","Low GDP") -> Low GDP | Q4: =IF(D4>=20,"Top performer","Low performer") -> Low performer
A5: Indonesia | B5: IDN | C5: Asia | D5: 2 | E5: 0 | F5: 1 | G5: 3 | H5: =IF(G5>=100,"Excellent","Needs improvement") -> Needs improvement | I5: 4940.55 | J5: 2023 | K5: 277.5 | L5: =D5/G5 -> 0.66666667 | M5: =E5/G5 -> 0 | N5: =F5/G5 -> 0.33333333 | O5: =I5/G5 -> 1646.85 | P5: =IF(I5>=50000,"High GDP","Low GDP") -> Low GDP | Q5: =IF(D5>=20,"Top performer","Low performer") -> Low performer
A6: Algeria | B6: DZA | C6: Africa | D6: 2 | E6: 0 | F6: 1 | G6: 3 | H6: =IF(G6>=100,"Excellent","Needs improvement") -> Needs improvement | I6: 5260.21 | J6: 2023 | K6: 45.6 | L6: =D6/G6 -> 0.66666667 | M6: =E6/G6 -> 0 | N6: =F6/G6 -> 0.33333333 | O6: =I6/G6 -> 1753.4033 | P6: =IF(I6>=50000,"High GDP","Low GDP") -> Low GDP | Q6: =IF(D6>=20,"Top performer","Low performer") -> Low performer
A7: Slovenia | B7: SVN | C7: Europe | D7: 2 | E7: 1 | F7: 0 | G7: 3 | H7: =IF(G7>=100,"Excellent","Needs improvement") -> Needs improvement | I7: 32163.51 | J7: 2023 | K7: 2.1 | L7: =D7/G7 -> 0.66666667 | M7: =E7/G7 -> 0.33333333 | N7: =F7/G7 -> 0 | O7: =I7/G7 -> 10721.17 | P7: =IF(I7>=50000,"High GDP","Low GDP") -> Low GDP | Q7: =IF(D7>=20,"Top performer","Low performer") -> Low performer
A8: Uzbekistan | B8: UZB | C8: Asia | D8: 8 | E8: 2 | F8: 3 | G8: 13 | H8: =IF(G8>=100,"Excellent","Needs improvement") -> Needs improvement | I8: 2496.11 | J8: 2023 | K8: 36.4 | L8: =D8/G8 -> 0.61538462 | M8: =E8/G8 -> 0.15384615 | N8: =F8/G8 -> 0.23076923 | O8: =I8/G8 -> 192.00846 | P8: =IF(I8>=50000,"High GDP","Low GDP") -> Low GDP | Q8: =IF(D8>=20,"Top performer","Low performer") -> Low performer
A9: Czech Republic | B9: CZE | C9: Europe | D9: 3 | E9: 0 | F9: 2 | G9: 5 | H9: =IF(G9>=100,"Excellent","Needs improvement") -> Needs improvement | I9: 30427.42 | J9: 2023 | K9: 10.9 | L9: =D9/G9 -> 0.6 | M9: =E9/G9 -> 0 | N9: =F9/G9 -> 0.4 | O9: =I9/G9 -> 6085.484 | P9: =IF(I9>=50000,"High GDP","Low GDP") -> Low GDP | Q9: =IF(D9>=20,"Top performer","Low performer") -> Low performer
A10: Serbia | B10: SRB | C10: Europe | D10: 3 | E10: 1 | F10: 1 | G10: 5 | H10: =IF(G10>=100,"Excellent","Needs improvement") -> Needs improvement | I10: 11360.96 | J10: 2023 | K10: 6.6 | L10: =D10/G10 -> 0.6 | M10: =E10/G10 -> 0.2 | N10: =F10/G10 -> 0.2 | O10: =I10/G10 -> 2272.192 | P10: =IF(I10>=50000,"High GDP","Low GDP") -> Low GDP | Q10: =IF(D10>=20,"Top performer","Low performer") -> Low performer
A11: Philippines | B11: PHL | C11: Asia | D11: 2 | E11: 0 | F11: 2 | G11: 4 | H11: =IF(G11>=100,"Excellent","Needs improvement") -> Needs improvement | I11: 3725.55 | J11: 2023 | K11: 117.3 | L11: =D11/G11 -> 0.5 | M11: =E11/G11 -> 0 | N11: =F11/G11 -> 0.5 | O11: =I11/G11 -> 931.3875 | P11: =IF(I11>=50000,"High GDP","Low GDP") -> Low GDP | Q11: =IF(D11>=20,"Top performer","Low performer") -> Low performer
A12: Uganda | B12: UGA | C12: Africa | D12: 1 | E12: 1 | F12: 0 | G12: 2 | H12: =IF(G12>=100,"Excellent","Needs improvement") -> Needs improvement | I12: 1014.21 | J12: 2023 | K12: 48.6 | L12: =D12/G12 -> 0.5 | M12: =E12/G12 -> 0.5 | N12: =F12/G12 -> 0 | O12: =I12/G12 -> 507.105 | P12: =IF(I12>=50000,"High GDP","Low GDP") -> Low GDP | Q12: =IF(D12>=20,"Top performer","Low performer") -> Low performer
A13: Morocco | B13: MAR | C13: Africa | D13: 1 | E13: 0 | F13: 1 | G13: 2 | H13: =IF(G13>=100,"Excellent","Needs improvement") -> Needs improvement | I13: 3672.11 | J13: 2023 | K13: 37.8 | L13: =D13/G13 -> 0.5 | M13: =E13/G13 -> 0 | N13: =F13/G13 -> 0.5 | O13: =I13/G13 -> 1836.055 | P13: =IF(I13>=50000,"High GDP","Low GDP") -> Low GDP | Q13: =IF(D13>=20,"Top performer","Low performer") -> Low performer
A14: Chile | B14: CHL | C14: South America | D14: 1 | E14: 1 | F14: 0 | G14: 2 | H14: =IF(G14>=100,"Excellent","Needs improvement") -> Needs improvement | I14: 17093.24 | J14: 2023 | K14: 19.6 | L14: =D14/G14 -> 0.5 | M14: =E14/G14 -> 0.5 | N14: =F14/G14 -> 0 | O14: =I14/G14 -> 8546.62 | P14: =IF(I14>=50000,"High GDP","Low GDP") -> Low GDP | Q14: =IF(D14>=20,"Top performer","Low performer") -> Low performer
... A91: Grenada | B91: GRD | C91: Caribbean | D91: 0 | E91: 0 | F91: 2 | G91: 2 | H91: =IF(G91>=100,"Excellent","Needs improvement") -> Needs improvement | I91: 10463.65 | J91: 2023 | K91: 0.1 | L91: =D91/G91 -> 0 | M91: =E91/G91 -> 0 | N91: =F91/G91 -> 1 | O91: =I91/G91 -> 5231.825 | P91: =IF(I91>=50000,"High GDP","Low GDP") -> Low GDP | Q91: =IF(D91>=20,"Top performer","Low performer") -> Low performer

Sheet Conditional Formatting
A1: Country | B1: Country_code | C1: Region | D1: Gold | E1: Silver | F1: Bronze | G1: Total | H1: Performance | I1: GDP | J1: GDP_year | K1: Population | L1: Gold % | M1: Silver% | N1: Bronze% | O1: GDP per medal | P1: GDP Category | Q1: Performace category
A2: Ireland | B2: IRL | C2: Europe | D2: 4 | E2: 0 | F2: 3 | H2: =IF(G2>=100,"Excellent","Needs improvement") -> Needs improvement | I2: 103684.88 | J2: 2023 | K2: 5.3 | L2: =D2/G2 -> #DIV/0! | M2: =E2/G2 -> #DIV/0! | N2: =F2/G2 -> #DIV/0! | O2: =I2/G2 -> #DIV/0! | P2: =IF(I2>=50000,"High GDP","Low GDP") -> High GDP | Q2: =IF(D2>=20,"Top performer","Low performer") -> Low performer
A3: Tajikistan | B3: TJK | C3: Asia | D3: 0 | E3: 0 | F3: 3 | G3: 3 | H3: =IF(G3>=100,"Excellent","Needs improvement") -> Needs improvement | I3: 1188.99 | J3: 2023 | K3: 10.1 | L3: =D3/G3 -> 0 | M3: =E3/G3 -> 0 | N3: =F3/G3 -> 1 | O3: =I3/G3 -> 396.33 | P3: =IF(I3>=50000,"High GDP","Low GDP") -> Low GDP | Q3: =IF(D3>=20,"Top performer","Low performer") -> Low performer
A4: Albania | B4: ALB | C4: Europe | D4: 0 | E4: 0 | F4: 2 | G4: 2 | H4: =IF(G4>=100,"Excellent","Needs improvement") -> Needs improvement | I4: 8367.78 | J4: 2023 | K4: 2.7 | L4: =D4/G4 -> 0 | M4: =E4/G4 -> 0 | N4: =F4/G4 -> 1 | O4: =I4/G4 -> 4183.89 | P4: =IF(I4>=50000,"High GDP","Low GDP") -> Low GDP | Q4: =IF(D4>=20,"Top performer","Low performer") -> Low performer
A5: Grenada | B5: GRD | C5: Caribbean | D5: 0 | E5: 0 | F5: 2 | G5: 2 | H5: =IF(G5>=100,"Excellent","Needs improvement") -> Needs improvement | I5: 10463.65 | J5: 2023 | K5: 0.1 | L5: =D5/G5 -> 0 | M5: =E5/G5 -> 0 | N5: =F5/G5 -> 1 | O5: =I5/G5 -> 5231.825 | P5: =IF(I5>=50000,"High GDP","Low GDP") -> Low GDP | Q5: =IF(D5>=20,"Top performer","Low performer") -> Low performer
A6: Malaysia | B6: MYS | C6: Asia | D6: 0 | E6: 0 | F6: 2 | G6: 2 | H6: =IF(G6>=100,"Excellent","Needs improvement") -> Needs improvement | I6: 11648.67 | J6: 2023 | K6: 34.3 | L6: =D6/G6 -> 0 | M6: =E6/G6 -> 0 | N6: =F6/G6 -> 1 | O6: =I6/G6 -> 5824.335 | P6: =IF(I6>=50000,"High GDP","Low GDP") -> Low GDP | Q6: =IF(D6>=20,"Top performer","Low performer") -> Low performer
A7: Puerto Rico | B7: PRI | C7: Caribbean | D7: 0 | E7: 0 | F7: 2 | G7: 2 | H7: =IF(G7>=100,"Excellent","Needs improvement") -> Needs improvement | I7: 36779.06 | J7: 2023 | K7: 3.2 | L7: =D7/G7 -> 0 | M7: =E7/G7 -> 0 | N7: =F7/G7 -> 1 | O7: =I7/G7 -> 18389.53 | P7: =IF(I7>=50000,"High GDP","Low GDP") -> Low GDP | Q7: =IF(D7>=20,"Top performer","Low performer") -> Low performer
A8: Cape Verde | B8: CPV | C8: Africa | D8: 0 | E8: 0 | F8: 1 | G8: 1 | H8: =IF(G8>=100,"Excellent","Needs improvement") -> Needs improvement | I8: 4321.58 | J8: 2023 | K8: 0.6 | L8: =D8/G8 -> 0 | M8: =E8/G8 -> 0 | N8: =F8/G8 -> 1 | O8: =I8/G8 -> 4321.58 | P8: =IF(I8>=50000,"High GDP","Low GDP") -> Low GDP | Q8: =IF(D8>=20,"Top performer","Low performer") -> Low performer
A9: Ivory Coast | B9: CIV | C9: Africa | D9: 0 | E9: 0 | F9: 1 | G9: 1 | H9: =IF(G9>=100,"Excellent","Needs improvement") -> Needs improvement | I9: 2728.8 | J9: 2023 | K9: 28.9 | L9: =D9/G9 -> 0 | M9: =E9/G9 -> 0 | N9: =F9/G9 -> 1 | O9: =I9/G9 -> 2728.8 | P9: =IF(I9>=50000,"High GDP","Low GDP") -> Low GDP | Q9: =IF(D9>=20,"Top performer","Low performer") -> Low performer
A10: Peru | B10: PER | C10: South America | D10: 0 | E10: 0 | F10: 1 | G10: 1 | H10: =IF(G10>=100,"Excellent","Needs improvement") -> Needs improvement | I10: 7789.87 | J10: 2023 | K10: 34.4 | L10: =D10/G10 -> 0 | M10: =E10/G10 -> 0 | N10: =F10/G10 -> 1 | O10: =I10/G10 -> 7789.87 | P10: =IF(I10>=50000,"High GDP","Low GDP") -> Low GDP | Q10: =IF(D10>=20,"Top performer","Low performer") -> Low performer
A11: Qatar | B11: QAT | C11: Asia | D11: 0 | E11: 0 | F11: 1 | G11: 1 | H11: =IF(G11>=100,"Excellent","Needs improvement") -> Needs improvement | I11: 87480.42 | J11: 2022 | K11: 2.7 | L11: =D11/G11 -> 0 | M11: =E11/G11 -> 0 | N11: =F11/G11 -> 1 | O11: =I11/G11 -> 87480.42 | P11: =IF(I11>=50000,"High GDP","Low GDP") -> High GDP | Q11: =IF(D11>=20,"Top performer","Low performer") -> Low performer
A12: Singapore | B12: SGP | C12: Asia | D12: 0 | E12: 0 | F12: 1 | G12: 1 | H12: =IF(G12>=100,"Excellent","Needs improvement") -> Needs improvement | I12: 84734.26 | J12: 2023 | K12: 5.9 | L12: =D12/G12 -> 0 | M12: =E12/G12 -> 0 | N12: =F12/G12 -> 1 | O12: =I12/G12 -> 84734.26 | P12: =IF(I12>=50000,"High GDP","Low GDP") -> High GDP | Q12: =IF(D12>=20,"Top performer","Low performer") -> Low performer
A13: Slovakia | B13: SVK | C13: Europe | D13: 0 | E13: 0 | F13: 1 | G13: 1 | H13: =IF(G13>=100,"Excellent","Needs improvement") -> Needs improvement | I13: 24470.24 | J13: 2023 | K13: 5.4 | L13: =D13/G13 -> 0 | M13: =E13/G13 -> 0 | N13: =F13/G13 -> 1 | O13: =I13/G13 -> 24470.24 | P13: =IF(I13>=50000,"High GDP","Low GDP") -> Low GDP | Q13: =IF(D13>=20,"Top performer","Low performer") -> Low performer
A14: Zambia | B14: ZMB | C14: Africa | D14: 0 | E14: 0 | F14: 1 | G14: 1 | H14: =IF(G14>=100,"Excellent","Needs improvement") -> Needs improvement | I14: 1369.13 | J14: 2023 | K14: 20.6 | L14: =D14/G14 -> 0 | M14: =E14/G14 -> 0 | N14: =F14/G14 -> 1 | O14: =I14/G14 -> 1369.13 | P14: =IF(I14>=50000,"High GDP","Low GDP") -> Low GDP | Q14: =IF(D14>=20,"Top performer","Low performer") -> Low performer
... A91: Panama | B91: PAN | C91: South America | D91: 0 | E91: 1 | F91: 0 | G91: 1 | H91: =IF(G91>=100,"Excellent","Needs improvement") -> Needs improvement | I91: 18661.77 | J91: 2023 | K91: 4.5 | L91: =D91/G91 -> 0 | M91: =E91/G91 -> 1 | N91: =F91/G91 -> 0 | O91: =I91/G91 -> 18661.77 | P91: =IF(I91>=50000,"High GDP","Low GDP") -> Low GDP | Q91: =IF(D91>=20,"Top performer","Low performer") -> Low performer

Sheet Filters
A1: Country | B1: Country_code | C1: Region | D1: Gold | E1: Silver | F1: Bronze | G1: Total | H1: Performance | I1: GDP | J1: GDP_year | K1: Population | L1: Gold % | M1: Silver% | N1: Bronze% | O1: GDP per medal | P1: GDP Category | Q1: Performace category
A2: United States | B2: USA | C2: North America | D2: 40 | E2: 44 | F2: 42 | G2: 126 | H2: =IF(G2>=100,"Excellent","Needs improvement") -> Excellent | I2: 81695.19 | J2: 2023 | K2: 334.9 | L2: =D2/G2 -> 0.31746032 | M2: =E2/G2 -> 0.34920635 | N2: =F2/G2 -> 0.33333333 | O2: =I2/G2 -> 648.37452 | P2: =IF(I2>=50000,"High GDP","Low GDP") -> High GDP | Q2: =IF(D2>=20,"Top performer","Low performer") -> Top performer
A3: China | B3: CHN | C3: Asia | D3: 40 | E3: 27 | F3: 24 | G3: 91 | H3: =IF(G3>=100,"Excellent","Needs improvement") -> Needs improvement | I3: 12614.06 | J3: 2023 | K3: 1410.7 | L3: =D3/G3 -> 0.43956044 | M3: =E3/G3 -> 0.2967033 | N3: =F3/G3 -> 0.26373626 | O3: =I3/G3 -> 138.61604 | P3: =IF(I3>=50000,"High GDP","Low GDP") -> Low GDP | Q3: =IF(D3>=20,"Top performer","Low performer") -> Top performer
A4: Japan | B4: JPN | C4: Asia | D4: 20 | E4: 12 | F4: 13 | G4: 45 | H4: =IF(G4>=100,"Excellent","Needs improvement") -> Needs improvement | I4: 33834.39 | J4: 2023 | K4: 124.5 | L4: =D4/G4 -> 0.44444444 | M4: =E4/G4 -> 0.26666667 | N4: =F4/G4 -> 0.28888889 | O4: =I4/G4 -> 751.87533 | P4: =IF(I4>=50000,"High GDP","Low GDP") -> Low GDP | Q4: =IF(D4>=20,"Top performer","Low performer") -> Top performer
A5: Australia | B5: AUS | C5: Oceania | D5: 18 | E5: 19 | F5: 16 | G5: 53 | H5: =IF(G5>=100,"Excellent","Needs improvement") -> Needs improvement | I5: 64711.77 | J5: 2023 | K5: 26.6 | L5: =D5/G5 -> 0.33962264 | M5: =E5/G5 -> 0.35849057 | N5: =F5/G5 -> 0.30188679 | O5: =I5/G5 -> 1220.9768 | P5: =IF(I5>=50000,"High GDP","Low GDP") -> High GDP | Q5: =IF(D5>=20,"Top performer","Low performer") -> Low performer
A6: France | B6: FRA | C6: Europe | D6: 16 | E6: 26 | F6: 22 | G6: 64 | H6: =IF(G6>=100,"Excellent","Needs improvement") -> Needs improvement | I6: 44460.82 | J6: 2023 | K6: 68.2 | L6: =D6/G6 -> 0.25 | M6: =E6/G6 -> 0.40625 | N6: =F6/G6 -> 0.34375 | O6: =I6/G6 -> 694.70031 | P6: =IF(I6>=50000,"High GDP","Low GDP") -> Low GDP | Q6: =IF(D6>=20,"Top performer","Low performer") -> Low performer
A7: Netherlands | B7: NLD | C7: Europe | D7: 15 | E7: 7 | F7: 12 | G7: 34 | H7: =IF(G7>=100,"Excellent","Needs improvement") -> Needs improvement | I7: 62536.73 | J7: 2023 | K7: 17.9 | L7: =D7/G7 -> 0.44117647 | M7: =E7/G7 -> 0.20588235 | N7: =F7/G7 -> 0.35294118 | O7: =I7/G7 -> 1839.3156 | P7: =IF(I7>=50000,"High GDP","Low GDP") -> High GDP | Q7: =IF(D7>=20,"Top performer","Low performer") -> Low performer
A8: Great Britain | B8: GBR | C8: Europe | D8: 14 | E8: 22 | F8: 29 | G8: 65 | H8: =IF(G8>=100,"Excellent","Needs improvement") -> Needs improvement | I8: 48866.6 | J8: 2023 | K8: 68.3 | L8: =D8/G8 -> 0.21538462 | M8: =E8/G8 -> 0.33846154 | N8: =F8/G8 -> 0.44615385 | O8: =I8/G8 -> 751.79385 | P8: =IF(I8>=50000,"High GDP","Low GDP") -> Low GDP | Q8: =IF(D8>=20,"Top performer","Low performer") -> Low performer
A9: South Korea | B9: KOR | C9: Asia | D9: 13 | E9: 9 | F9: 10 | G9: 32 | H9: =IF(G9>=100,"Excellent","Needs improvement") -> Needs improvement | I9: 33121.37 | J9: 2023 | K9: 51.7 | L9: =D9/G9 -> 0.40625 | M9: =E9/G9 -> 0.28125 | N9: =F9/G9 -> 0.3125 | O9: =I9/G9 -> 1035.0428 | P9: =IF(I9>=50000,"High GDP","Low GDP") -> Low GDP | Q9: =IF(D9>=20,"Top performer","Low performer") -> Low performer
A10: Italy | B10: ITA | C10: Europe | D10: 12 | E10: 13 | F10: 15 | G10: 40 | H10: =IF(G10>=100,"Excellent","Needs improvement") -> Needs improvement | I10: 38373.17 | J10: 2023 | K10: 58.8 | L10: =D10/G10 -> 0.3 | M10: =E10/G10 -> 0.325 | N10: =F10/G10 -> 0.375 | O10: =I10/G10 -> 959.32925 | P10: =IF(I10>=50000,"High GDP","Low GDP") -> Low GDP | Q10: =IF(D10>=20,"Top performer","Low performer") -> Low performer
A11: Germany | B11: DEU | C11: Europe | D11: 12 | E11: 13 | F11: 8 | G11: 33 | H11: =IF(G11>=100,"Excellent","Needs improvement") -> Needs improvement | I11: 52745.76 | J11: 2023 | K11: 84.5 | L11: =D11/G11 -> 0.36363636 | M11: =E11/G11 -> 0.39393939 | N11: =F11/G11 -> 0.24242424 | O11: =I11/G11 -> 1598.3564 | P11: =IF(I11>=50000,"High GDP","Low GDP") -> High GDP | Q11: =IF(D11>=20,"Top performer","Low performer") -> Low performer
A12: New Zealand | B12: NZL | C12: Oceania | D12: 10 | E12: 7 | F12: 3 | G12: 20 | H12: =IF(G12>=100,"Excellent","Needs improvement") -> Needs improvement | I12: 48527.83 | J12: 2023 | K12: 5.2 | L12: =D12/G12 -> 0.5 | M12: =E12/G12 -> 0.35 | N12: =F12/G12 -> 0.15 | O12: =I12/G12 -> 2426.3915 | P12: =IF(I12>=50000,"High GDP","Low GDP") -> Low GDP | Q12: =IF(D12>=20,"Top performer","Low performer") -> Low performer
A13: Canada | B13: CAN | C13: North America | D13: 9 | E13: 7 | F13: 11 | G13: 27 | H13: =IF(G13>=100,"Excellent","Needs improvement") -> Needs improvement | I13: 53371.7 | J13: 2023 | K13: 40.1 | L13: =D13/G13 -> 0.33333333 | M13: =E13/G13 -> 0.25925926 | N13: =F13/G13 -> 0.40740741 | O13: =I13/G13 -> 1976.7296 | P13: =IF(I13>=50000,"High GDP","Low GDP") -> High GDP | Q13: =IF(D13>=20,"Top performer","Low performer") -> Low performer
... A91: Zambia | B91: ZMB | C91: Africa | D91: 0 | E91: 0 | F91: 1 | G91: 1 | H91: =IF(G91>=100,"Excellent","Needs improvement") -> Needs improvement | I91: 1369.13 | J91: 2023 | K91: 20.6 | L91: =D91/G91 -> 0 | M91: =E91/G91 -> 0 | N91: =F91/G91 -> 1 | O91: =I91/G91 -> 1369.13 | P91: =IF(I91>=50000,"High GDP","Low GDP") -> Low GDP | Q91: =IF(D91>=20,"Top performer","Low performer") -> Low performer
